Workbook

Sheet Summary
B2: 特斯拉 2026—2030 财务预测与 DCF 估值
B3: Tesla, Inc. (NASDAQ: TSLA) | USD mn except per-share; editable scenario in Assumptions!C4 | Valuation date: 2026-10-26
B4: Active scenario | C4: =Assumptions!C4 -> Base
B6: Valuation summary
B7: Enterprise value | C7: =DCF!C30 -> 72137.102
B8: Equity value | C8: =DCF!C34 -> 107461.1
B9: Implied value / share | C9: =DCF!C36 -> 27.18636
B10: Market price (2026-10-26 close) | C10: =Assumptions!C9 -> 394.62
B11: Implied upside / (downside) | C11: =DCF!C38 -> -0.93110749
B12: Chosen WACC | C12: =DCF!C23 -> 0.12996791
B13: Terminal growth | C13: =DCF!C24 -> 0.025
B14: PV terminal / EV | C14: =DCF!C39 -> 0.96155393
B17: Scenario comparison — live independent calculations
B18: Metric | C18: Bear | D18: Base | E18: Bull
B19: Enterprise value | C19: ='Scenario DCF'!C132 -> 2798.9464 | D19: ='Scenario DCF'!C38 -> 72137.102 | E19: ='Scenario DCF'!C85 -> 247091.81
B20: Equity value | C20: ='Scenario DCF'!C136 -> 38122.946 | D20: ='Scenario DCF'!C42 -> 107461.1 | E20: ='Scenario DCF'!C89 -> 282415.81
B21: Implied value / share | C21: ='Scenario DCF'!C138 -> 9.6446448 | D21: ='Scenario DCF'!C44 -> 27.18636 | E21: ='Scenario DCF'!C91 -> 71.447786
B22: WACC | C22: ='Scenario DCF'!C125 -> 0.13996791 | D22: ='Scenario DCF'!C31 -> 0.12996791 | E22: ='Scenario DCF'!C78 -> 0.11996791
B23: Terminal growth | C23: ='Scenario DCF'!C126 -> 0.02 | D23: ='Scenario DCF'!C32 -> 0.025 | E23: ='Scenario DCF'!C79 -> 0.03
B24: PV terminal / EV | C24: ='Scenario DCF'!C141 -> 5.8289982 | D24: ='Scenario DCF'!C47 -> 0.96155393 | E24: ='Scenario DCF'!C94 -> 0.80718168
B27: Financial trajectory — active scenario
B28: Metric | C28: 2024A | D28: 2025A | E28: 9M2026A | F28: Q4 2026E | G28: 2026E | H28: 2027E | I28: 2028E | J28: 2029E | K28: 2030E
B29: Revenue | C29: =IS!C9 -> 97690 | D29: =IS!D9 -> 94827 | E29: =IS!E9 -> 78669 | F29: =IS!F9 -> 30090 | G29: =IS!G9 -> 108759 | H29: =IS!H9 -> 127671.61 | I29: =IS!I9 -> 150424.13 | J29: =IS!J9 -> 173874.63 | K29: =IS!K9 -> 196987.87
B30: Gross margin | C30: =IS!C30 -> 0.17862627 | D30: =IS!D30 -> 0.18026511 | E30: =IS!E30 -> 0.19022741 | F30: =IS!F30 -> 0.19190429 | G30: =IS!G30 -> 0.19069135 | H30: =IS!H30 -> 0.19659972 | I30: =IS!I30 -> 0.20233519 | J30: =IS!J30 -> 0.208804 | K30: =IS!K30 -> 0.21509736
B31: Operating income | C31: =IS!C18 -> 7076 | D31: =IS!D18 -> 4355 | E31: =IS!E18 -> 2057 | F31: =IS!F18 -> 960 | G31: =IS!G18 -> 3017 | H31: =IS!H18 -> 5949.4619 | I31: =IS!I18 -> 9376.7174 | J31: =IS!J18 -> 13702.015 | K31: =IS!K18 -> 18733.025
B32: Operating margin | C32: =IS!C31 -> 0.072433207 | D32: =IS!D31 -> 0.045925738 | E32: =IS!E31 -> 0.02614753 | F32: =IS!F31 -> 0.031904287 | G32: =IS!G31 -> 0.027740233 | H32: =IS!H31 -> 0.046599724 | I32: =IS!I31 -> 0.062335193 | J32: =IS!J31 -> 0.078803995 | K32: =IS!K31 -> 0.095097355
B33: Net income to common | C33: =IS!C26 -> 7091 | D33: =IS!D26 -> 3794 | E33: =IS!E26 -> 2378 | F33: =IS!F26 -> 1026.5666 | G33: =IS!G26 -> 3404.5666 | H33: =IS!H26 -> 5697.9208 | I33: =IS!I26 -> 8320.7594 | J33: =IS!J26 -> 11871.318 | K33: =IS!K26 -> 16215.627
B36: How to use / key conventions
B37: 1. Change Assumptions!C4 to Base / Bull / Bear. Edit amber cells for operating and valuation assumptions.
B38: 2. 2026E = 9M2026A + Q4 2026E. DCF counts Q4 2026E only, then FY2027–FY2030.
B39: 3. Historical data are SEC/Tesla IR actuals; forecasts are analyst assumptions, not company guidance except noted capex anchor.
B40: 4. DCF uses year-end discounting, normalized terminal reinvestment, and no SBC add-back.
B41: 5. Equity bridge: EV + cash/ST investments − debt/finance leases − minority interests. Bridge date 2026-09-30.
B42: 6. Per-share uses 3,952.758mn actual shares at 2026-10-15. Full CEO award dilution stress is in Sensitivity.
B43: 7. Robotaxi, Optimus and SpaceX upside are embedded only through scenario drivers; no separate option valuation.
B44: 8. See Checks for integrity; Sources and Raw Data for lineage; Sensitivity for WACC/g/reinvestment/margin/revenue/dilution.

Sheet Assumptions
B2: 经营与估值假设 / Scenario inputs
B3: Tesla, Inc. (NASDAQ: TSLA) | Blue/amber cells are editable inputs | Valuation date: 2026-10-26
B4: Active scenario | C4: Base
B5: Switch in C4; all active statements, DCF and sensitivities update. Scenario DCF computes all three independently.
B7: Valuation inputs
B8: Valuation date | C8: 46321 | D8: User instruction | E8: DCF valuation point
B9: Share price (USD) | C9: 394.62 | D9: S8 | E9: 2026-10-26 close; cross-check only
B10: Shares outstanding (mn) | C10: 3952.7579 | D10: S4 | E10: Actual common shares at 2026-10-15; latest cover-page count
B11: Cash + short-term investments | C11: 45447 | D11: S4 | E11: 2026-09-30 bridge balance
B12: Debt + finance leases | C12: 9523 | D12: S4 | E12: Current 1,387 + non-current 8,136
B13: Minority interests | C13: 600 | D13: S4 | E13: Redeemable NCI 54 + NCI 546
B14: 10-year UST risk-free rate | C14: 0.05 | D14: S7 | E14: 2026-10-23 daily par yield
B15: Levered beta | C15: 1.916 | D15: S9 | E15: Yahoo Finance beta; no relevering adjustment
B16: US equity risk premium | C16: 0.042 | D16: S10 | E16: Damodaran Oct-2026 implied ERP, secondary citation
B17: Pre-tax cost of debt | C17: 0.06 | D17: S4 + analyst assumption | E17: Rf + 1.0%; within disclosed facility spread context
B18: WACC tax rate | C18: 0.21 | D18: Analyst assumption | E18: Normalized US federal statutory anchor
B19: Market capitalization | C19: =C9*C10 -> 1559837.3 | D19: Calculated | E19: Price × latest actual shares
B20: Cost of equity | C20: =C14+C15*C16 -> 0.130472 | D20: CAPM | E20: Rf + beta × ERP; no extra premium
B21: Equity weight | C21: =C19/(C19+C12) -> 0.99393192 | D21: Calculated | E21: Market equity / (market equity + debt)
B22: Debt weight | C22: =C12/(C19+C12) -> 0.0060680775 | D22: Calculated | E22: Debt / (market equity + debt)
B23: Suggested WACC | C23: =C20*C21+C17*(1-C18)*C22 -> 0.12996791 | D23: Calculated | E23: Market-value weights; after-tax debt
B27: Base scenario — Q4 2026E and FY2027E–FY2030E
B28: Driver | C28: Unit | D28: Source | E28: Rationale | F28: Q4 2026E | G28: 2027E | H28: 2028E | I28: 2029E | J28: 2030E
B29: Vehicle deliveries | C29: units | D29: Analyst assumption; see S4/S5/S11 | E29: Q4 backlog and capacity utilization; later autonomy/new products and factory ramp | F29: 520000 | G29: — | H29: — | I29: — | J29: —
B30: Delivery growth | C30: % | D30: Analyst assumption; see S4/S5/S11 | E30: Base scales below management's aspirational 5m capacity goal; Bull faster; Bear weak demand | F30: — | G30: 0.15 | H30: 0.14 | I30: 0.12 | J30: 0.1
B31: Automotive revenue / delivery | C31: USD/unit | D31: Analyst assumption; see S4/S5/S11 | E31: Q3 implied ~42.3k; includes credits/leasing and ancillary mix | F31: 42000 | G31: — | H31: — | I31: — | J31: —
B32: Auto revenue / delivery change | C32: % | D32: Analyst assumption; see S4/S5/S11 | E32: Software/mix vs price competition | F32: — | G32: 0.01 | H32: 0.01 | I32: 0.01 | J32: 0.01
B33: Storage deployments | C33: GWh | D33: Analyst assumption; see S4/S5/S11 | E33: 9M actual 36.0; Megafactory Texas and backlog support Q4 | F33: 15 | G33: — | H33: — | I33: — | J33: —
B34: Storage deployment growth | C34: % | D34: Analyst assumption; see S4/S5/S11 | E34: Data-center/grid demand and new capacity; no assumed unlimited backlog conversion | F34: — | G34: 0.35 | H34: 0.3 | I34: 0.25 | J34: 0.2
B35: Energy revenue / GWh | C35: USD mn/GWh | D35: Analyst assumption; see S4/S5/S11 | E35: Q3 tariff-refund distortions; Q4 below 2025 realized unit revenue | F35: 230 | G35: — | H35: — | I35: — | J35: —
B36: Energy unit revenue change | C36: % | D36: Analyst assumption; see S4/S5/S11 | E36: Price/mix and storage product competition | F36: — | G36: -0.02 | H36: -0.02 | I36: -0.02 | J36: -0.02
B37: Services & other revenue | C37: USD mn | D37: Analyst assumption; see S4/S5/S11 | E37: Q4 anchored near Q3 4,605 with fleet, charging and insurance growth | F37: 4800 | G37: — | H37: — | I37: — | J37: —
B38: Services revenue growth | C38: % | D38: Analyst assumption; see S4/S5/S11 | E38: Installed fleet, FSD/subscriptions, Supercharging; Robotaxi not separately valued | F38: — | G38: 0.25 | H38: 0.22 | I38: 0.2 | J38: 0.18
B39: Automotive gross margin | C39: % | D39: Analyst assumption; see S4/S5/S11 | E39: 9M cost/mix base; credits included; scale and software vs pricing | F39: 0.185 | G39: 0.19 | H39: 0.195 | I39: 0.2 | J39: 0.205
B40: Energy gross margin | C40: % | D40: Analyst assumption; see S4/S5/S11 | E40: Q3 33.1% included tariff benefits; normalized forward margins | F40: 0.28 | G40: 0.28 | H40: 0.285 | I40: 0.29 | J40: 0.295
B41: Services gross margin | C41: % | D41: Analyst assumption; see S4/S5/S11 | E41: Q3 record 15.9%; gradual operating leverage | F41: 0.16 | G41: 0.165 | H41: 0.17 | I41: 0.18 | J41: 0.19
B42: R&D / revenue | C42: % | D42: Analyst assumption; see S4/S5/S11 | E42: Elevated SI, chip, Optimus and new-product spend; gradual commercialization leverage; Bear includes cost control | F42: 0.09 | G42: 0.085 | H42: 0.08 | I42: 0.075 | J42: 0.07
B43: SG&A / revenue | C43: % | D43: Analyst assumption; see S4/S5/S11 | E43: CEO award and expansion costs; scale leverage differs by scenario; Bear includes cost control | F43: 0.07 | G43: 0.065 | H43: 0.06 | I43: 0.055 | J43: 0.05
B44: D&A / opening fixed assets | C44: % | D44: Analyst assumption; see S4/S5/S11 | E44: Q4 quarterly rate; annual thereafter; anchored to recent D&A and asset base | F44: 0.032 | G44: 0.12 | H44: 0.12 | I44: 0.12 | J44: 0.12
B45: Capital expenditures | C45: USD mn | D45: Analyst assumption; see S4/S5/S11 | E45: 9M 13,014; official >20bn FY2026 implies >6,986 Q4; SI/fab/robotics drive later spend; Bear slows expansion | F45: 7000 | G45: 22000 | H45: 24000 | I45: 22000 | J45: 20000
...

Sheet Drivers
B2: 经营驱动 / Active scenario
B3: Tesla, Inc. (NASDAQ: TSLA) | USD mn; selected scenario flows from Assumptions | Valuation date: 2026-10-26
B4: Active scenario | C4: =Assumptions!C4 -> Base
B5: Fiscal period | C5: 2024A | D5: 2025A | E5: 9M2026A | F5: Q4 2026E | G5: 2026E | H5: 2027E | I5: 2028E | J5: 2029E | K5: 2030E
B6: Revenue build
B7: Vehicle deliveries | C7: 1789226 | D7: 1636129 | E7: 1324681 | F7: =CHOOSE(MATCH(Assumptions!$C$4,{"Base","Bull","Bear"},0),Assumptions!F29,Assumptions!F68,Assumptions!F107) -> 520000 | G7: =E7+F7 -> 1844681 | H7: =G7*(1+H8) -> 2121383.1 | I7: =H7*(1+I8) -> 2418376.8 | J7: =I7*(1+J8) -> 2708582 | K7: =J7*(1+K8) -> 2979440.2
B8: Delivery growth | D8: =D7/C7-1 -> -0.085566049 | E8: =E7/D7-1 -> -0.19035663 | F8: =CHOOSE(MATCH(Assumptions!$C$4,{"Base","Bull","Bear"},0),Assumptions!F30,Assumptions!F69,Assumptions!F108) -> — | G8: =G7/D7-1 -> 0.12746672 | H8: =CHOOSE(MATCH(Assumptions!$C$4,{"Base","Bull","Bear"},0),Assumptions!G30,Assumptions!G69,Assumptions!G108) -> 0.15 | I8: =CHOOSE(MATCH(Assumptions!$C$4,{"Base","Bull","Bear"},0),Assumptions!H30,Assumptions!H69,Assumptions!H108) -> 0.14 | J8: =CHOOSE(MATCH(Assumptions!$C$4,{"Base","Bull","Bear"},0),Assumptions!I30,Assumptions!I69,Assumptions!I108) -> 0.12 | K8: =CHOOSE(MATCH(Assumptions!$C$4,{"Base","Bull","Bear"},0),Assumptions!J30,Assumptions!J69,Assumptions!J108) -> 0.1
B9: Automotive revenue / delivery | C9: =C11*1000000/C7 -> 43074.491 | D9: =D11*1000000/D7 -> 42494.204 | E9: =E11*1000000/E7 -> 43263.246 | F9: =CHOOSE(MATCH(Assumptions!$C$4,{"Base","Bull","Bear"},0),Assumptions!F31,Assumptions!F70,Assumptions!F109) -> 42000 | G9: =G11*1000000/G7 -> 42907.148 | H9: =F9*(1+H10) -> 42420 | I9: =H9*(1+I10) -> 42844.2 | J9: =I9*(1+J10) -> 43272.642 | K9: =J9*(1+K10) -> 43705.368
B10: Auto revenue / delivery change | F10: =CHOOSE(MATCH(Assumptions!$C$4,{"Base","Bull","Bear"},0),Assumptions!F32,Assumptions!F71,Assumptions!F110) -> — | H10: =CHOOSE(MATCH(Assumptions!$C$4,{"Base","Bull","Bear"},0),Assumptions!G32,Assumptions!G71,Assumptions!G110) -> 0.01 | I10: =CHOOSE(MATCH(Assumptions!$C$4,{"Base","Bull","Bear"},0),Assumptions!H32,Assumptions!H71,Assumptions!H110) -> 0.01 | J10: =CHOOSE(MATCH(Assumptions!$C$4,{"Base","Bull","Bear"},0),Assumptions!I32,Assumptions!I71,Assumptions!I110) -> 0.01 | K10: =CHOOSE(MATCH(Assumptions!$C$4,{"Base","Bull","Bear"},0),Assumptions!J32,Assumptions!J71,Assumptions!J110) -> 0.01
B11: Automotive revenue | C11: 77070 | D11: 69526 | E11: 57310 | F11: =F7*F9/1000000 -> 21840 | G11: =E11+F11 -> 79150 | H11: =H7*H9/1000000 -> 89989.073 | I11: =I7*I9/1000000 -> 103613.42 | J11: =J7*J9/1000000 -> 117207.5 | K11: =K7*K9/1000000 -> 130217.53
B12: Storage deployments (GWh) | C12: 31.4 | D12: 46.7 | E12: 36 | F12: =CHOOSE(MATCH(Assumptions!$C$4,{"Base","Bull","Bear"},0),Assumptions!F33,Assumptions!F72,Assumptions!F111) -> 15 | G12: =E12+F12 -> 51 | H12: =G12*(1+H13) -> 68.85 | I12: =H12*(1+I13) -> 89.505 | J12: =I12*(1+J13) -> 111.88125 | K12: =J12*(1+K13) -> 134.2575
B13: Storage deployment growth | D13: =D12/C12-1 -> 0.48726115 | E13: =E12/D12-1 -> -0.22912206 | F13: =CHOOSE(MATCH(Assumptions!$C$4,{"Base","Bull","Bear"},0),Assumptions!F34,Assumptions!F73,Assumptions!F112) -> — | G13: =G12/D12-1 -> 0.092077088 | H13: =CHOOSE(MATCH(Assumptions!$C$4,{"Base","Bull","Bear"},0),Assumptions!G34,Assumptions!G73,Assumptions!G112) -> 0.35 | I13: =CHOOSE(MATCH(Assumptions!$C$4,{"Base","Bull","Bear"},0),Assumptions!H34,Assumptions!H73,Assumptions!H112) -> 0.3 | J13: =CHOOSE(MATCH(Assumptions!$C$4,{"Base","Bull","Bear"},0),Assumptions!I34,Assumptions!I73,Assumptions!I112) -> 0.25 | K13: =CHOOSE(MATCH(Assumptions!$C$4,{"Base","Bull","Bear"},0),Assumptions!J34,Assumptions!J73,Assumptions!J112) -> 0.2
B14: Energy revenue / GWh | C14: =C16/C12 -> 321.21019 | D14: =D16/D12 -> 273.46895 | E14: =E16/E12 -> 234.11111 | F14: =CHOOSE(MATCH(Assumptions!$C$4,{"Base","Bull","Bear"},0),Assumptions!F35,Assumptions!F74,Assumptions!F113) -> 230 | G14: =G16/G12 -> 232.90196 | H14: =F14*(1+H15) -> 225.4 | I14: =H14*(1+I15) -> 220.892 | J14: =I14*(1+J15) -> 216.47416 | K14: =J14*(1+K15) -> 212.14468
B15: Energy unit revenue change | F15: =CHOOSE(MATCH(Assumptions!$C$4,{"Base","Bull","Bear"},0),Assumptions!F36,Assumptions!F75,Assumptions!F114) -> — | H15: =CHOOSE(MATCH(Assumptions!$C$4,{"Base","Bull","Bear"},0),Assumptions!G36,Assumptions!G75,Assumptions!G114) -> -0.02 | I15: =CHOOSE(MATCH(Assumptions!$C$4,{"Base","Bull","Bear"},0),Assumptions!H36,Assumptions!H75,Assumptions!H114) -> -0.02 | J15: =CHOOSE(MATCH(Assumptions!$C$4,{"Base","Bull","Bear"},0),Assumptions!I36,Assumptions!I75,Assumptions!I114) -> -0.02 | K15: =CHOOSE(MATCH(Assumptions!$C$4,{"Base","Bull","Bear"},0),Assumptions!J36,Assumptions!J75,Assumptions!J114) -> -0.02
B16: Energy revenue | C16: 10086 | D16: 12771 | E16: 8428 | F16: =F12*F14 -> 3450 | G16: =E16+F16 -> 11878 | H16: =H12*H14 -> 15518.79 | I16: =I12*I14 -> 19770.938 | J16: =J12*J14 -> 24219.4 | K16: =K12*K14 -> 28482.014
B17: Services & other revenue | C17: 10534 | D17: 12530 | E17: 12931 | F17: =CHOOSE(MATCH(Assumptions!$C$4,{"Base","Bull","Bear"},0),Assumptions!F37,Assumptions!F76,Assumptions!F115) -> 4800 | G17: =E17+F17 -> 17731 | H17: =G17*(1+H18) -> 22163.75 | I17: =H17*(1+I18) -> 27039.775 | J17: =I17*(1+J18) -> 32447.73 | K17: =J17*(1+K18) -> 38288.321
B18: Services growth | D18: =D17/C17-1 -> 0.18948168 | E18: =E17/D17-1 -> 0.032003192 | F18: =CHOOSE(MATCH(Assumptions!$C$4,{"Base","Bull","Bear"},0),Assumptions!F38,Assumptions!F77,Assumptions!F116) -> — | G18: =G17/D17-1 -> 0.4150838 | H18: =CHOOSE(MATCH(Assumptions!$C$4,{"Base","Bull","Bear"},0),Assumptions!G38,Assumptions!G77,Assumptions!G116) -> 0.25 | I18: =CHOOSE(MATCH(Assumptions!$C$4,{"Base","Bull","Bear"},0),Assumptions!H38,Assumptions!H77,Assumptions!H116) -> 0.22 | J18: =CHOOSE(MATCH(Assumptions!$C$4,{"Base","Bull","Bear"},0),Assumptions!I38,Assumptions!I77,Assumptions!I116) -> 0.2 | K18: =CHOOSE(MATCH(Assumptions!$C$4,{"Base","Bull","Bear"},0),Assumptions!J38,Assumptions!J77,Assumptions!J116) -> 0.18
B19: Total revenue | C19: 97690 | D19: 94827 | E19: 78669 | F19: =F11+F16+F17 -> 30090 | G19: =E19+F19 -> 108759 | H19: =H11+H16+H17 -> 127671.61 | I19: =I11+I16+I17 -> 150424.13 | J19: =J11+J16+J17 -> 173874.63 | K19: =K11+K16+K17 -> 196987.87
B21: Margins, costs and investment
B22: Automotive gross margin | C22: 0.18420916 | D22: 0.1777896 | E22: 0.18654685 | F22: =CHOOSE(MATCH(Assumptions!$C$4,{"Base","Bull","Bear"},0),Assumptions!F39,Assumptions!F78,Assumptions!F117) -> 0.185 | G22: =F22 -> 0.185 | H22: =CHOOSE(MATCH(Assumptions!$C$4,{"Base","Bull","Bear"},0),Assumptions!G39,Assumptions!G78,Assumptions!G117) -> 0.19 | I22: =CHOOSE(MATCH(Assumptions!$C$4,{"Base","Bull","Bear"},0),Assumptions!H39,Assumptions!H78,Assumptions!H117) -> 0.195 | J22: =CHOOSE(MATCH(Assumptions!$C$4,{"Base","Bull","Bear"},0),Assumptions!I39,Assumptions!I78,Assumptions!I117) -> 0.2 | K22: =CHOOSE(MATCH(Assumptions!$C$4,{"Base","Bull","Bear"},0),Assumptions!J39,Assumptions!J78,Assumptions!J117) -> 0.205
B23: Energy gross margin | C23: 0.26174896 | D23: 0.29770574 | E23: 0.30208828 | F23: =CHOOSE(MATCH(Assumptions!$C$4,{"Base","Bull","Bear"},0),Assumptions!F40,Assumptions!F79,Assumptions!F118) -> 0.28 | G23: =F23 -> 0.28 | H23: =CHOOSE(MATCH(Assumptions!$C$4,{"Base","Bull","Bear"},0),Assumptions!G40,Assumptions!G79,Assumptions!G118) -> 0.28 | I23: =CHOOSE(MATCH(Assumptions!$C$4,{"Base","Bull","Bear"},0),Assumptions!H40,Assumptions!H79,Assumptions!H118) -> 0.285 | J23: =CHOOSE(MATCH(Assumptions!$C$4,{"Base","Bull","Bear"},0),Assumptions!I40,Assumptions!I79,Assumptions!I118) -> 0.29 | K23: =CHOOSE(MATCH(Assumptions!$C$4,{"Base","Bull","Bear"},0),Assumptions!J40,Assumptions!J79,Assumptions!J118) -> 0.295
B24: Services gross margin | C24: 0.058192519 | D24: 0.074301676 | E24: 0.13363236 | F24: =CHOOSE(MATCH(Assumptions!$C$4,{"Base","Bull","Bear"},0),Assumptions!F41,Assumptions!F80,Assumptions!F119) -> 0.16 | G24: =F24 -> 0.16 | H24: =CHOOSE(MATCH(Assumptions!$C$4,{"Base","Bull","Bear"},0),Assumptions!G41,Assumptions!G80,Assumptions!G119) -> 0.165 | I24: =CHOOSE(MATCH(Assumptions!$C$4,{"Base","Bull","Bear"},0),Assumptions!H41,Assumptions!H80,Assumptions!H119) -> 0.17 | J24: =CHOOSE(MATCH(Assumptions!$C$4,{"Base","Bull","Bear"},0),Assumptions!I41,Assumptions!I80,Assumptions!I119) -> 0.18 | K24: =CHOOSE(MATCH(Assumptions!$C$4,{"Base","Bull","Bear"},0),Assumptions!J41,Assumptions!J80,Assumptions!J119) -> 0.19
B25: R&D / revenue | C25: 0.046473539 | D25: 0.067607327 | E25: 0.089971908 | F25: =CHOOSE(MATCH(Assumptions!$C$4,{"Base","Bull","Bear"},0),Assumptions!F42,Assumptions!F81,Assumptions!F120) -> 0.09 | G25: =F25 -> 0.09 | H25: =CHOOSE(MATCH(Assumptions!$C$4,{"Base","Bull","Bear"},0),Assumptions!G42,Assumptions!G81,Assumptions!G120) -> 0.085 | I25: =CHOOSE(MATCH(Assumptions!$C$4,{"Base","Bull","Bear"},0),Assumptions!H42,Assumptions!H81,Assumptions!H120) -> 0.08 | J25: =CHOOSE(MATCH(Assumptions!$C$4,{"Base","Bull","Bear"},0),Assumptions!I42,Assumptions!I81,Assumptions!I120) -> 0.075 | K25: =CHOOSE(MATCH(Assumptions!$C$4,{"Base","Bull","Bear"},0),Assumptions!J42,Assumptions!J81,Assumptions!J120) -> 0.07
B26: SG&A / revenue | C26: 0.052717781 | D26: 0.061522562 | E26: 0.074107971 | F26: =CHOOSE(MATCH(Assumptions!$C$4,{"Base","Bull","Bear"},0),Assumptions!F43,Assumptions!F82,Assumptions!F121) -> 0.07 | G26: =F26 -> 0.07 | H26: =CHOOSE(MATCH(Assumptions!$C$4,{"Base","Bull","Bear"},0),Assumptions!G43,Assumptions!G82,Assumptions!G121) -> 0.065 | I26: =CHOOSE(MATCH(Assumptions!$C$4,{"Base","Bull","Bear"},0),Assumptions!H43,Assumptions!H82,Assumptions!H121) -> 0.06 | J26: =CHOOSE(MATCH(Assumptions!$C$4,{"Base","Bull","Bear"},0),Assumptions!I43,Assumptions!I82,Assumptions!I121) -> 0.055 | K26: =CHOOSE(MATCH(Assumptions!$C$4,{"Base","Bull","Bear"},0),Assumptions!J43,Assumptions!J82,Assumptions!J121) -> 0.05
B27: D&A / opening fixed assets | F27: =CHOOSE(MATCH(Assumptions!$C$4,{"Base","Bull","Bear"},0),Assumptions!F44,Assumptions!F83,Assumptions!F122) -> 0.032 | H27: =CHOOSE(MATCH(Assumptions!$C$4,{"Base","Bull","Bear"},0),Assumptions!G44,Assumptions!G83,Assumptions!G122) -> 0.12 | I27: =CHOOSE(MATCH(Assumptions!$C$4,{"Base","Bull","Bear"},0),Assumptions!H44,Assumptions!H83,Assumptions!H122) -> 0.12 | J27: =CHOOSE(MATCH(Assumptions!$C$4,{"Base","Bull","Bear"},0),Assumptions!I44,Assumptions!I83,Assumptions!I122) -> 0.12 | K27: =CHOOSE(MATCH(Assumptions!$C$4,{"Base","Bull","Bear"},0),Assumptions!J44,Assumptions!J83,Assumptions!J122) -> 0.12
B28: Capital expenditures | C28: 11342 | D28: 8527 | E28: 13014 | F28: =CHOOSE(MATCH(Assumptions!$C$4,{"Base","Bull","Bear"},0),Assumptions!F45,Assumptions!F84,Assumptions!F123) -> 7000 | G28: =E28+F28 -> 20014 | H28: =CHOOSE(MATCH(Assumptions!$C$4,{"Base","Bull","Bear"},0),Assumptions!G45,Assumptions!G84,Assumptions!G123) -> 22000 | I28: =CHOOSE(MATCH(Assumptions!$C$4,{"Base","Bull","Bear"},0),Assumptions!H45,Assumptions!H84,Assumptions!H123) -> 24000 | J28: =CHOOSE(MATCH(Assumptions!$C$4,{"Base","Bull","Bear"},0),Assumptions!I45,Assumptions!I84,Assumptions!I123) -> 22000 | K28: =CHOOSE(MATCH(Assumptions!$C$4,{"Base","Bull","Bear"},0),Assumptions!J45,Assumptions!J84,Assumptions!J123) -> 20000
B29: SBC / revenue | C29: 0.020462688 | D29: 0.029791093 | E29: 0.042532637 | F29: =CHOOSE(MATCH(Assumptions!$C$4,{"Base","Bull","Bear"},0),Assumptions!F53,Assumptions!F92,Assumptions!F131) -> 0.04 | G29: =F29 -> 0.04 | H29: =CHOOSE(MATCH(Assumptions!$C$4,{"Base","Bull","Bear"},0),Assumptions!G53,Assumptions!G92,Assumptions!G131) -> 0.04 | I29: =CHOOSE(MATCH(Assumptions!$C$4,{"Base","Bull","Bear"},0),Assumptions!H53,Assumptions!H92,Assumptions!H131) -> 0.038 | J29: =CHOOSE(MATCH(Assumptions!$C$4,{"Base","Bull","Bear"},0),Assumptions!I53,Assumptions!I92,Assumptions!I131) -> 0.035 | K29: =CHOOSE(MATCH(Assumptions!$C$4,{"Base","Bull","Bear"},0),Assumptions!J53,Assumptions!J92,Assumptions!J131) -> 0.03
B30: Normalized tax rate | C30: 0.20433815 | D30: 0.2696097 | E30: 0.201121 | F30: =CHOOSE(MATCH(Assumptions!$C$4,{"Base","Bull","Bear"},0),Assumptions!F54,Assumptions!F93,Assumptions!F132) -> 0.21 | H30: =CHOOSE(MATCH(Assumptions!$C$4,{"Base","Bull","Bear"},0),Assumptions!G54,Assumptions!G93,Assumptions!G132) -> 0.21 | I30: =CHOOSE(MATCH(Assumptions!$C$4,{"Base","Bull","Bear"},0),Assumptions!H54,Assumptions!H93,Assumptions!H132) -> 0.21 | J30: =CHOOSE(MATCH(Assumptions!$C$4,{"Base","Bull","Bear"},0),Assumptions!I54,Assumptions!I93,Assumptions!I132) -> 0.21 | K30: =CHOOSE(MATCH(Assumptions!$C$4,{"Base","Bull","Bear"},0),Assumptions!J54,Assumptions!J93,Assumptions!J132) -> 0.21
B31: Cash & investment yield | F31: =CHOOSE(MATCH(Assumptions!$C$4,{"Base","Bull","Bear"},0),Assumptions!F55,Assumptions!F94,Assumptions!F133) -> 0.01 | H31: =CHOOSE(MATCH(Assumptions!$C$4,{"Base","Bull","Bear"},0),Assumptions!G55,Assumptions!G94,Assumptions!G133) -> 0.04 | I31: =CHOOSE(MATCH(Assumptions!$C$4,{"Base","Bull","Bear"},0),Assumptions!H55,Assumptions!H94,Assumptions!H133) -> 0.04 | J31: =CHOOSE(MATCH(Assumptions!$C$4,{"Base","Bull","Bear"},0),Assumptions!I55,Assumptions!I94,Assumptions!I133) -> 0.04 | K31: =CHOOSE(MATCH(Assumptions!$C$4,{"Base","Bull","Bear"},0),Assumptions!J55,Assumptions!J94,Assumptions!J133) -> 0.04
B32: Debt interest rate | F32: =CHOOSE(MATCH(Assumptions!$C$4,{"Base","Bull","Bear"},0),Assumptions!F56,Assumptions!F95,Assumptions!F134) -> 0.01 | H32: =CHOOSE(MATCH(Assumptions!$C$4,{"Base","Bull","Bear"},0),Assumptions!G56,Assumptions!G95,Assumptions!G134) -> 0.04 | I32: =CHOOSE(MATCH(Assumptions!$C$4,{"Base","Bull","Bear"},0),Assumptions!H56,Assumptions!H95,Assumptions!H134) -> 0.04 | J32: =CHOOSE(MATCH(Assumptions!$C$4,{"Base","Bull","Bear"},0),Assumptions!I56,Assumptions!I95,Assumptions!I134) -> 0.04 | K32: =CHOOSE(MATCH(Assumptions!$C$4,{"Base","Bull","Bear"},0),Assumptions!J56,Assumptions!J95,Assumptions!J134) -> 0.04
B33: Other non-operating income | F33: =CHOOSE(MATCH(Assumptions!$C$4,{"Base","Bull","Bear"},0),Assumptions!F57,Assumptions!F96,Assumptions!F135) -> 0 | G33: =E33+F33 -> 0 | H33: =CHOOSE(MATCH(Assumptions!$C$4,{"Base","Bull","Bear"},0),Assumptions!G57,Assumptions!G96,Assumptions!G135) -> 0 | I33: =CHOOSE(MATCH(Assumptions!$C$4,{"Base","Bull","Bear"},0),Assumptions!H57,Assumptions!H96,Assumptions!H135) -> 0 | J33: =CHOOSE(MATCH(Assumptions!$C$4,{"Base","Bull","Bear"},0),Assumptions!I57,Assumptions!I96,Assumptions!I135) -> 0 | K33: =CHOOSE(MATCH(Assumptions!$C$4,{"Base","Bull","Bear"},0),Assumptions!J57,Assumptions!J96,Assumptions!J135) -> 0
B34: NCI share of net income | F34: =CHOOSE(MATCH(Assumptions!$C$4,{"Base","Bull","Bear"},0),Assumptions!F58,Assumptions!F97,Assumptions!F136) -> 0.015 | H34: =CHOOSE(MATCH(Assumptions!$C$4,{"Base","Bull","Bear"},0),Assumptions!G58,Assumptions!G97,Assumptions!G136) -> 0.015 | I34: =CHOOSE(MATCH(Assumptions!$C$4,{"Base","Bull","Bear"},0),Assumptions!H58,Assumptions!H97,Assumptions!H136) -> 0.015 | J34: =CHOOSE(MATCH(Assumptions!$C$4,{"Base","Bull","Bear"},0),Assumptions!I58,Assumptions!I97,Assumptions!I136) -> 0.015 | K34: =CHOOSE(MATCH(Assumptions!$C$4,{"Base","Bull","Bear"},0),Assumptions!J58,Assumptions!J97,Assumptions!J136) -> 0.015
B36: Working capital
B37: DSO | F37: =CHOOSE(MATCH(Assumptions!$C$4,{"Base","Bull","Bear"},0),Assumptions!F46,Assumptions!F85,Assumptions!F124) -> 15 | H37: =CHOOSE(MATCH(Assumptions!$C$4,{"Base","Bull","Bear"},0),Assumptions!G46,Assumptions!G85,Assumptions!G124) -> 15 | I37: =CHOOSE(MATCH(Assumptions!$C$4,{"Base","Bull","Bear"},0),Assumptions!H46,Assumptions!H85,Assumptions!H124) -> 15 | J37: =CHOOSE(MATCH(Assumptions!$C$4,{"Base","Bull","Bear"},0),Assumptions!I46,Assumptions!I85,Assumptions!I124) -> 15 | K37: =CHOOSE(MATCH(Assumptions!$C$4,{"Base","Bull","Bear"},0),Assumptions!J46,Assumptions!J85,Assumptions!J124) -> 15
B38: DIO | F38: =CHOOSE(MATCH(Assumptions!$C$4,{"Base","Bull","Bear"},0),Assumptions!F47,Assumptions!F86,Assumptions!F125) -> 55 | H38: =CHOOSE(MATCH(Assumptions!$C$4,{"Base","Bull","Bear"},0),Assumptions!G47,Assumptions!G86,Assumptions!G125) -> 55 | I38: =CHOOSE(MATCH(Assumptions!$C$4,{"Base","Bull","Bear"},0),Assumptions!H47,Assumptions!H86,Assumptions!H125) -> 55 | J38: =CHOOSE(MATCH(Assumptions!$C$4,{"Base","Bull","Bear"},0),Assumptions!I47,Assumptions!I86,Assumptions!I125) -> 55 | K38: =CHOOSE(MATCH(Assumptions!$C$4,{"Base","Bull","Bear"},0),Assumptions!J47,Assumptions!J86,Assumptions!J125) -> 55
B39: DPO | F39: =CHOOSE(MATCH(Assumptions!$C$4,{"Base","Bull","Bear"},0),Assumptions!F48,Assumptions!F87,Assumptions!F126) -> 65 | H39: =CHOOSE(MATCH(Assumptions!$C$4,{"Base","Bull","Bear"},0),Assumptions!G48,Assumptions!G87,Assumptions!G126) -> 65 | I39: =CHOOSE(MATCH(Assumptions!$C$4,{"Base","Bull","Bear"},0),Assumptions!H48,Assumptions!H87,Assumptions!H126) -> 65 | J39: =CHOOSE(MATCH(Assumptions!$C$4,{"Base","Bull","Bear"},0),Assumptions!I48,Assumptions!I87,Assumptions!I126) -> 65 | K39: =CHOOSE(MATCH(Assumptions!$C$4,{"Base","Bull","Bear"},0),Assumptions!J48,Assumptions!J87,Assumptions!J126) -> 65
B40: Prepaid / revenue | F40: =CHOOSE(MATCH(Assumptions!$C$4,{"Base","Bull","Bear"},0),Assumptions!F49,Assumptions!F88,Assumptions!F127) -> 0.055 | H40: =CHOOSE(MATCH(Assumptions!$C$4,{"Base","Bull","Bear"},0),Assumptions!G49,Assumptions!G88,Assumptions!G127) -> 0.055 | I40: =CHOOSE(MATCH(Assumptions!$C$4,{"Base","Bull","Bear"},0),Assumptions!H49,Assumptions!H88,Assumptions!H127) -> 0.055 | J40: =CHOOSE(MATCH(Assumptions!$C$4,{"Base","Bull","Bear"},0),Assumptions!I49,Assumptions!I88,Assumptions!I127) -> 0.055 | K40: =CHOOSE(MATCH(Assumptions!$C$4,{"Base","Bull","Bear"},0),Assumptions!J49,Assumptions!J88,Assumptions!J127) -> 0.055
B41: Accrued / revenue | F41: =CHOOSE(MATCH(Assumptions!$C$4,{"Base","Bull","Bear"},0),Assumptions!F50,Assumptions!F89,Assumptions!F128) -> 0.15 | H41: =CHOOSE(MATCH(Assumptions!$C$4,{"Base","Bull","Bear"},0),Assumptions!G50,Assumptions!G89,Assumptions!G128) -> 0.15 | I41: =CHOOSE(MATCH(Assumptions!$C$4,{"Base","Bull","Bear"},0),Assumptions!H50,Assumptions!H89,Assumptions!H128) -> 0.15 | J41: =CHOOSE(MATCH(Assumptions!$C$4,{"Base","Bull","Bear"},0),Assumptions!I50,Assumptions!I89,Assumptions!I128) -> 0.15 | K41: =CHOOSE(MATCH(Assumptions!$C$4,{"Base","Bull","Bear"},0),Assumptions!J50,Assumptions!J89,Assumptions!J128) -> 0.15
B42: Deferred revenue / revenue | F42: =CHOOSE(MATCH(Assumptions!$C$4,{"Base","Bull","Bear"},0),Assumptions!F51,Assumptions!F90,Assumptions!F129) -> 0.08 | H42: =CHOOSE(MATCH(Assumptions!$C$4,{"Base","Bull","Bear"},0),Assumptions!G51,Assumptions!G90,Assumptions!G129) -> 0.08 | I42: =CHOOSE(MATCH(Assumptions!$C$4,{"Base","Bull","Bear"},0),Assumptions!H51,Assumptions!H90,Assumptions!H129) -> 0.08 | J42: =CHOOSE(MATCH(Assumptions!$C$4,{"Base","Bull","Bear"},0),Assumptions!I51,Assumptions!I90,Assumptions!I129) -> 0.08 | K42: =CHOOSE(MATCH(Assumptions!$C$4,{"Base","Bull","Bear"},0),Assumptions!J51,Assumptions!J90,Assumptions!J129) -> 0.08
B43: Other LT liabilities / revenue | F43: =CHOOSE(MATCH(Assumptions!$C$4,{"Base","Bull","Bear"},0),Assumptions!F52,Assumptions!F91,Assumptions!F130) -> 0.13 | H43: =CHOOSE(MATCH(Assumptions!$C$4,{"Base","Bull","Bear"},0),Assumptions!G52,Assumptions!G91,Assumptions!G130) -> 0.13 | I43: =CHOOSE(MATCH(Assumptions!$C$4,{"Base","Bull","Bear"},0),Assumptions!H52,Assumptions!H91,Assumptions!H130) -> 0.13 | J43: =CHOOSE(MATCH(Assumptions!$C$4,{"Base","Bull","Bear"},0),Assumptions!I52,Assumptions!I91,Assumptions!I130) -> 0.13 | K43: =CHOOSE(MATCH(Assumptions!$C$4,{"Base","Bull","Bear"},0),Assumptions!J52,Assumptions!J91,Assumptions!J130) -> 0.13
...

Sheet IS
B2: 利润表 / Income Statement
B3: Tesla, Inc. (NASDAQ: TSLA) | USD mn except per-share data | Valuation date: 2026-10-26
B5: Fiscal period | C5: 2024A | D5: 2025A | E5: 9M2026A | F5: Q4 2026E | G5: 2026E | H5: 2027E | I5: 2028E | J5: 2029E | K5: 2030E
B6: Automotive revenue | C6: ='Raw Data'!C6 -> 77070 | D6: ='Raw Data'!D6 -> 69526 | E6: ='Raw Data'!E6 -> 57310 | F6: =Drivers!F11 -> 21840 | G6: =E6+F6 -> 79150 | H6: =Drivers!H11 -> 89989.073 | I6: =Drivers!I11 -> 103613.42 | J6: =Drivers!J11 -> 117207.5 | K6: =Drivers!K11 -> 130217.53
B7: Energy generation & storage revenue | C7: ='Raw Data'!C7 -> 10086 | D7: ='Raw Data'!D7 -> 12771 | E7: ='Raw Data'!E7 -> 8428 | F7: =Drivers!F16 -> 3450 | G7: =E7+F7 -> 11878 | H7: =Drivers!H16 -> 15518.79 | I7: =Drivers!I16 -> 19770.938 | J7: =Drivers!J16 -> 24219.4 | K7: =Drivers!K16 -> 28482.014
B8: Services & other revenue | C8: ='Raw Data'!C8 -> 10534 | D8: ='Raw Data'!D8 -> 12530 | E8: ='Raw Data'!E8 -> 12931 | F8: =Drivers!F17 -> 4800 | G8: =E8+F8 -> 17731 | H8: =Drivers!H17 -> 22163.75 | I8: =Drivers!I17 -> 27039.775 | J8: =Drivers!J17 -> 32447.73 | K8: =Drivers!K17 -> 38288.321
B9: Total revenue | C9: ='Raw Data'!C9 -> 97690 | D9: ='Raw Data'!D9 -> 94827 | E9: ='Raw Data'!E9 -> 78669 | F9: =Drivers!F19 -> 30090 | G9: =E9+F9 -> 108759 | H9: =Drivers!H19 -> 127671.61 | I9: =Drivers!I19 -> 150424.13 | J9: =Drivers!J19 -> 173874.63 | K9: =Drivers!K19 -> 196987.87
B10: Automotive cost of revenue | C10: ='Raw Data'!C10 -> 62873 | D10: ='Raw Data'!D10 -> 57165 | E10: ='Raw Data'!E10 -> 46619 | F10: =Drivers!F11*(1-Drivers!F22) -> 17799.6 | G10: =E10+F10 -> 64418.6 | H10: =Drivers!H11*(1-Drivers!H22) -> 72891.149 | I10: =Drivers!I11*(1-Drivers!I22) -> 83408.802 | J10: =Drivers!J11*(1-Drivers!J22) -> 93766 | K10: =Drivers!K11*(1-Drivers!K22) -> 103522.94
B11: Energy cost of revenue | C11: ='Raw Data'!C11 -> 7446 | D11: ='Raw Data'!D11 -> 8969 | E11: ='Raw Data'!E11 -> 5882 | F11: =Drivers!F16*(1-Drivers!F23) -> 2484 | G11: =E11+F11 -> 8366 | H11: =Drivers!H16*(1-Drivers!H23) -> 11173.529 | I11: =Drivers!I16*(1-Drivers!I23) -> 14136.221 | J11: =Drivers!J16*(1-Drivers!J23) -> 17195.774 | K11: =Drivers!K16*(1-Drivers!K23) -> 20079.82
B12: Services & other cost of revenue | C12: ='Raw Data'!C12 -> 9921 | D12: ='Raw Data'!D12 -> 11599 | E12: ='Raw Data'!E12 -> 11203 | F12: =Drivers!F17*(1-Drivers!F24) -> 4032 | G12: =E12+F12 -> 15235 | H12: =Drivers!H17*(1-Drivers!H24) -> 18506.731 | I12: =Drivers!I17*(1-Drivers!I24) -> 22443.013 | J12: =Drivers!J17*(1-Drivers!J24) -> 26607.139 | K12: =Drivers!K17*(1-Drivers!K24) -> 31013.54
B13: Total cost of revenue | C13: ='Raw Data'!C13 -> 80240 | D13: ='Raw Data'!D13 -> 77733 | E13: ='Raw Data'!E13 -> 63704 | F13: =SUM(F10:F12) -> 24315.6 | G13: =E13+F13 -> 88019.6 | H13: =SUM(H10:H12) -> 102571.41 | I13: =SUM(I10:I12) -> 119988.04 | J13: =SUM(J10:J12) -> 137568.91 | K13: =SUM(K10:K12) -> 154616.3
B14: Gross profit | C14: ='Raw Data'!C14 -> 17450 | D14: ='Raw Data'!D14 -> 17094 | E14: ='Raw Data'!E14 -> 14965 | F14: =F9-F13 -> 5774.4 | G14: =E14+F14 -> 20739.4 | H14: =H9-H13 -> 25100.204 | I14: =I9-I13 -> 30436.096 | J14: =J9-J13 -> 36305.717 | K14: =K9-K13 -> 42371.569
B15: Research & development | C15: ='Raw Data'!C15 -> 4540 | D15: ='Raw Data'!D15 -> 6411 | E15: ='Raw Data'!E15 -> 7078 | F15: =Drivers!F19*Drivers!F25 -> 2708.1 | G15: =E15+F15 -> 9786.1 | H15: =Drivers!H19*Drivers!H25 -> 10852.087 | I15: =Drivers!I19*Drivers!I25 -> 12033.931 | J15: =Drivers!J19*Drivers!J25 -> 13040.597 | K15: =Drivers!K19*Drivers!K25 -> 13789.151
B16: Selling, general & administrative | C16: ='Raw Data'!C16 -> 5150 | D16: ='Raw Data'!D16 -> 5834 | E16: ='Raw Data'!E16 -> 5830 | F16: =Drivers!F19*Drivers!F26 -> 2106.3 | G16: =E16+F16 -> 7936.3 | H16: =Drivers!H19*Drivers!H26 -> 8298.6549 | I16: =Drivers!I19*Drivers!I26 -> 9025.4479 | J16: =Drivers!J19*Drivers!J26 -> 9563.1046 | K16: =Drivers!K19*Drivers!K26 -> 9849.3934
B17: Restructuring & other | C17: ='Raw Data'!C17 -> 684 | D17: ='Raw Data'!D17 -> 494 | E17: ='Raw Data'!E17 -> 0 | F17: =0 -> 0 | G17: =E17+F17 -> 0 | H17: =0 -> 0 | I17: =0 -> 0 | J17: =0 -> 0 | K17: =0 -> 0
B18: Operating income | C18: ='Raw Data'!C18 -> 7076 | D18: ='Raw Data'!D18 -> 4355 | E18: ='Raw Data'!E18 -> 2057 | F18: =F14-F15-F16-F17 -> 960 | G18: =E18+F18 -> 3017 | H18: =H14-H15-H16-H17 -> 5949.4619 | I18: =I14-I15-I16-I17 -> 9376.7174 | J18: =J14-J15-J16-J17 -> 13702.015 | K18: =K14-K15-K16-K17 -> 18733.025
B19: Interest income | C19: ='Raw Data'!C19 -> 1569 | D19: ='Raw Data'!D19 -> 1680 | E19: ='Raw Data'!E19 -> 1301 | F19: =('Raw Data'!E29+'Raw Data'!E30)*Drivers!F31 -> 454.47 | G19: =E19+F19 -> 1755.47 | H19: =(BS!F6+BS!F7)*Drivers!H31 -> 1753.852 | I19: =(BS!H6+BS!H7)*Drivers!I31 -> 1697.2045 | J19: =(BS!I6+BS!I7)*Drivers!J31 -> 1934.7268 | K19: =(BS!J6+BS!J7)*Drivers!K31 -> 2486.5855
B20: Interest expense | C20: ='Raw Data'!C20 -> -350 | D20: ='Raw Data'!D20 -> -338 | E20: ='Raw Data'!E20 -> -263 | F20: =-'Raw Data'!E79*Drivers!F32 -> -95.23 | G20: =E20+F20 -> -358.23 | H20: =-BS!F18*Drivers!H32 -> -380.92 | I20: =-BS!H18*Drivers!I32 -> -380.92 | J20: =-BS!I18*Drivers!J32 -> -380.92 | K20: =-BS!J18*Drivers!K32 -> -380.92
B21: Other income (expense), net | C21: ='Raw Data'!C21 -> 695 | D21: ='Raw Data'!D21 -> -419 | E21: ='Raw Data'!E21 -> -62 | F21: =Drivers!F33 -> 0 | G21: =E21+F21 -> -62 | H21: =Drivers!H33 -> 0 | I21: =Drivers!I33 -> 0 | J21: =Drivers!J33 -> 0 | K21: =Drivers!K33 -> 0
B22: Pre-tax income | C22: ='Raw Data'!C22 -> 8990 | D22: ='Raw Data'!D22 -> 5278 | E22: ='Raw Data'!E22 -> 3033 | F22: =F18+F19+F20+F21 -> 1319.24 | G22: =E22+F22 -> 4352.24 | H22: =H18+H19+H20+H21 -> 7322.3939 | I22: =I18+I19+I20+I21 -> 10693.002 | J22: =J18+J19+J20+J21 -> 15255.822 | K22: =K18+K19+K20+K21 -> 20838.691
B23: Income tax | C23: ='Raw Data'!C23 -> 1837 | D23: ='Raw Data'!D23 -> 1423 | E23: ='Raw Data'!E23 -> 610 | F23: =F22*Drivers!F30 -> 277.0404 | G23: =E23+F23 -> 887.0404 | H23: =H22*Drivers!H30 -> 1537.7027 | I23: =I22*Drivers!I30 -> 2245.5304 | J23: =J22*Drivers!J30 -> 3203.7227 | K23: =K22*Drivers!K30 -> 4376.125
B24: Net income | C24: ='Raw Data'!C24 -> 7153 | D24: ='Raw Data'!D24 -> 3855 | E24: ='Raw Data'!E24 -> 2423 | F24: =F22-F23 -> 1042.1996 | G24: =E24+F24 -> 3465.1996 | H24: =H22-H23 -> 5784.6912 | I24: =I22-I23 -> 8447.4715 | J24: =J22-J23 -> 12052.1 | K24: =K22-K23 -> 16462.566
B25: Net income attributable to NCI | C25: ='Raw Data'!C25 -> 62 | D25: ='Raw Data'!D25 -> 61 | E25: ='Raw Data'!E25 -> 45 | F25: =F24*Drivers!F34 -> 15.632994 | G25: =E25+F25 -> 60.632994 | H25: =H24*Drivers!H34 -> 86.770368 | I25: =I24*Drivers!I34 -> 126.71207 | J25: =J24*Drivers!J34 -> 180.78149 | K25: =K24*Drivers!K34 -> 246.93848
B26: Net income attributable to common | C26: ='Raw Data'!C26 -> 7091 | D26: ='Raw Data'!D26 -> 3794 | E26: ='Raw Data'!E26 -> 2378 | F26: =F24-F25 -> 1026.5666 | G26: =E26+F26 -> 3404.5666 | H26: =H24-H25 -> 5697.9208 | I26: =I24-I25 -> 8320.7594 | J26: =J24-J25 -> 11871.318 | K26: =K24-K25 -> 16215.627
B27: Diluted weighted average shares | C27: ='Raw Data'!C27 -> 3498 | D27: ='Raw Data'!D27 -> 3528 | E27: ='Raw Data'!E27 -> 3539 | F27: =Assumptions!$C$10 -> 3952.7579 | G27: =Assumptions!$C$10 -> 3952.7579 | H27: =Assumptions!$C$10 -> 3952.7579 | I27: =Assumptions!$C$10 -> 3952.7579 | J27: =Assumptions!$C$10 -> 3952.7579 | K27: =Assumptions!$C$10 -> 3952.7579
B28: Diluted EPS | C28: ='Raw Data'!C28 -> 2.04 | D28: ='Raw Data'!D28 -> 1.08 | E28: ='Raw Data'!E28 -> 0.67 | F28: =F26/F27 -> 0.25970895 | G28: =G26/G27 -> 0.86131421 | H28: =H26/H27 -> 1.4415051 | I28: =I26/I27 -> 2.1050516 | J28: =J26/J27 -> 3.0033 | K28: =K26/K27 -> 4.1023577
B29: Revenue growth | D29: =D9/C9-1 -> -0.029306992 | E29: =E9/D9-1 -> -0.17039451 | G29: =G9/F9-1 -> 2.6144566 | H29: =H9/G9-1 -> 0.1738947 | I29: =I9/H9-1 -> 0.17821126 | J29: =J9/I9-1 -> 0.15589584 | K29: =K9/J9-1 -> 0.13293048
B30: Gross margin | C30: =C14/C9 -> 0.17862627 | D30: =D14/D9 -> 0.18026511 | E30: =E14/E9 -> 0.19022741 | F30: =F14/F9 -> 0.19190429 | G30: =G14/G9 -> 0.19069135 | H30: =H14/H9 -> 0.19659972 | I30: =I14/I9 -> 0.20233519 | J30: =J14/J9 -> 0.208804 | K30: =K14/K9 -> 0.21509736
B31: Operating margin | C31: =C18/C9 -> 0.072433207 | D31: =D18/D9 -> 0.045925738 | E31: =E18/E9 -> 0.02614753 | F31: =F18/F9 -> 0.031904287 | G31: =G18/G9 -> 0.027740233 | H31: =H18/H9 -> 0.046599724 | I31: =I18/I9 -> 0.062335193 | J31: =J18/J9 -> 0.078803995 | K31: =K18/K9 -> 0.095097355

Sheet BS
B2: 资产负债表 / Balance Sheet
B3: Tesla, Inc. (NASDAQ: TSLA) | USD mn; Q4 2026E = FY2026E ending balance | Valuation date: 2026-10-26
B5: Fiscal period | C5: 2024A | D5: 2025A | E5: 9M2026A | F5: Q4 2026E | G5: 2026E | H5: 2027E | I5: 2028E | J5: 2029E | K5: 2030E
B6: Cash & cash equivalents | C6: ='Raw Data'!C29 -> 16139 | D6: ='Raw Data'!D29 -> 16513 | E6: ='Raw Data'!E29 -> 17853 | F6: =CF!F31 -> 16252.301 | G6: =F6 -> 16252.301 | H6: =CF!H31 -> 14836.114 | I6: =CF!I31 -> 20774.17 | J6: =CF!J31 -> 34570.637 | K6: =CF!K31 -> 55731.513
B7: Short-term investments | C7: ='Raw Data'!C30 -> 20424 | D7: ='Raw Data'!D30 -> 27546 | E7: ='Raw Data'!E30 -> 27594 | F7: =E7 -> 27594 | G7: =F7 -> 27594 | H7: =F7 -> 27594 | I7: =H7 -> 27594 | J7: =I7 -> 27594 | K7: =J7 -> 27594
B8: Accounts receivable | C8: ='Raw Data'!C31 -> 4418 | D8: ='Raw Data'!D31 -> 4576 | E8: ='Raw Data'!E31 -> 4636 | F8: =Drivers!F19*Drivers!F52*Drivers!F37/365 -> 4946.3014 | G8: =F8 -> 4946.3014 | H8: =Drivers!H19*Drivers!H52*Drivers!H37/365 -> 5246.7786 | I8: =Drivers!I19*Drivers!I52*Drivers!I37/365 -> 6181.8137 | J8: =Drivers!J19*Drivers!J52*Drivers!J37/365 -> 7145.5327 | K8: =Drivers!K19*Drivers!K52*Drivers!K37/365 -> 8095.3918
B9: Inventory | C9: ='Raw Data'!C32 -> 12017 | D9: ='Raw Data'!D32 -> 12392 | E9: ='Raw Data'!E32 -> 14092 | F9: =IS!F13*Drivers!F52*Drivers!F38/365 -> 14655.978 | G9: =F9 -> 14655.978 | H9: =IS!H13*Drivers!H52*Drivers!H38/365 -> 15455.966 | I9: =IS!I13*Drivers!I52*Drivers!I38/365 -> 18080.389 | J9: =IS!J13*Drivers!J52*Drivers!J38/365 -> 20729.562 | K9: =IS!K13*Drivers!K52*Drivers!K38/365 -> 23298.346
B10: Prepaid & other current assets | C10: ='Raw Data'!C33 -> 5362 | D10: ='Raw Data'!D33 -> 7615 | E10: ='Raw Data'!E33 -> 6227 | F10: =Drivers!F19*Drivers!F52*Drivers!F40 -> 6619.8 | G10: =F10 -> 6619.8 | H10: =Drivers!H19*Drivers!H52*Drivers!H40 -> 7021.9387 | I10: =Drivers!I19*Drivers!I52*Drivers!I40 -> 8273.3273 | J10: =Drivers!J19*Drivers!J52*Drivers!J40 -> 9563.1046 | K10: =Drivers!K19*Drivers!K52*Drivers!K40 -> 10834.333
B11: Total current assets | C11: ='Raw Data'!C34 -> 58360 | D11: ='Raw Data'!D34 -> 68642 | E11: ='Raw Data'!E34 -> 70402 | F11: =SUM(F6:F10) -> 70068.38 | G11: =F11 -> 70068.38 | H11: =SUM(H6:H10) -> 70154.797 | I11: =SUM(I6:I10) -> 80903.7 | J11: =SUM(J6:J10) -> 99602.836 | K11: =SUM(K6:K10) -> 125553.58
B12: Fixed & leased operating assets, net | C12: ='Raw Data'!C76 -> 46341 | D12: ='Raw Data'!D76 -> 50159 | E12: ='Raw Data'!E76 -> 59091 | F12: =Schedules!F9 -> 64200.088 | G12: =F12 -> 64200.088 | H12: =Schedules!H9 -> 78496.077 | I12: =Schedules!I9 -> 93076.548 | J12: =Schedules!J9 -> 103907.36 | K12: =Schedules!K9 -> 111438.48
B13: Other assets | C13: ='Raw Data'!C77 -> 17369 | D13: ='Raw Data'!D77 -> 19005 | E13: ='Raw Data'!E77 -> 28024 | F13: =E13 -> 28024 | G13: =F13 -> 28024 | H13: =F13 -> 28024 | I13: =H13 -> 28024 | J13: =I13 -> 28024 | K13: =J13 -> 28024
B14: Total assets | C14: ='Raw Data'!C42 -> 122070 | D14: ='Raw Data'!D42 -> 137806 | E14: ='Raw Data'!E42 -> 157517 | F14: =F11+F12+F13 -> 162292.47 | G14: =F14 -> 162292.47 | H14: =H11+H12+H13 -> 176674.87 | I14: =I11+I12+I13 -> 202004.25 | J14: =J11+J12+J13 -> 231534.2 | K14: =K11+K12+K13 -> 265016.06
B15: Accounts payable | C15: ='Raw Data'!C43 -> 12474 | D15: ='Raw Data'!D43 -> 13371 | E15: ='Raw Data'!E43 -> 17239 | F15: =IS!F13*Drivers!F52*Drivers!F39/365 -> 17320.701 | G15: =F15 -> 17320.701 | H15: =IS!H13*Drivers!H52*Drivers!H39/365 -> 18266.141 | I15: =IS!I13*Drivers!I52*Drivers!I39/365 -> 21367.733 | J15: =IS!J13*Drivers!J52*Drivers!J39/365 -> 24498.573 | K15: =IS!K13*Drivers!K52*Drivers!K39/365 -> 27534.409
B16: Accrued liabilities & other | C16: ='Raw Data'!C44 -> 10723 | D16: ='Raw Data'!D44 -> 13279 | E16: ='Raw Data'!E44 -> 17205 | F16: =Drivers!F19*Drivers!F52*Drivers!F41 -> 18054 | G16: =F16 -> 18054 | H16: =Drivers!H19*Drivers!H52*Drivers!H41 -> 19150.742 | I16: =Drivers!I19*Drivers!I52*Drivers!I41 -> 22563.62 | J16: =Drivers!J19*Drivers!J52*Drivers!J41 -> 26081.194 | K16: =Drivers!K19*Drivers!K52*Drivers!K41 -> 29548.18
B17: Deferred revenue | C17: ='Raw Data'!C78 -> 6485 | D17: ='Raw Data'!D78 -> 7055 | E17: ='Raw Data'!E78 -> 8787 | F17: =Drivers!F19*Drivers!F52*Drivers!F42 -> 9628.8 | G17: =F17 -> 9628.8 | H17: =Drivers!H19*Drivers!H52*Drivers!H42 -> 10213.729 | I17: =Drivers!I19*Drivers!I52*Drivers!I42 -> 12033.931 | J17: =Drivers!J19*Drivers!J52*Drivers!J42 -> 13909.97 | K17: =Drivers!K19*Drivers!K52*Drivers!K42 -> 15759.029
B18: Debt & finance leases | C18: ='Raw Data'!C79 -> 8213 | D18: ='Raw Data'!D79 -> 8376 | E18: ='Raw Data'!E79 -> 9523 | F18: =Schedules!F13 -> 9523 | G18: =F18 -> 9523 | H18: =Schedules!H13 -> 9523 | I18: =Schedules!I13 -> 9523 | J18: =Schedules!J13 -> 9523 | K18: =Schedules!K13 -> 9523
B19: Other long-term liabilities | C19: ='Raw Data'!C49 -> 10495 | D19: ='Raw Data'!D49 -> 12860 | E19: ='Raw Data'!E49 -> 14874 | F19: =Drivers!F19*Drivers!F52*Drivers!F43 -> 15646.8 | G19: =F19 -> 15646.8 | H19: =Drivers!H19*Drivers!H52*Drivers!H43 -> 16597.31 | I19: =Drivers!I19*Drivers!I52*Drivers!I43 -> 19555.137 | J19: =Drivers!J19*Drivers!J52*Drivers!J43 -> 22603.702 | K19: =Drivers!K19*Drivers!K52*Drivers!K43 -> 25608.423
B20: Total liabilities | C20: ='Raw Data'!C50 -> 48390 | D20: ='Raw Data'!D50 -> 54941 | E20: ='Raw Data'!E50 -> 67628 | F20: =SUM(F15:F19) -> 70173.301 | G20: =F20 -> 70173.301 | H20: =SUM(H15:H19) -> 73750.922 | I20: =SUM(I15:I19) -> 85043.42 | J20: =SUM(J15:J19) -> 96616.44 | K20: =SUM(K15:K19) -> 107973.04
B21: Redeemable NCI | C21: ='Raw Data'!C51 -> 63 | D21: ='Raw Data'!D51 -> 58 | E21: ='Raw Data'!E51 -> 54 | F21: =E21 -> 54 | G21: =F21 -> 54 | H21: =F21 -> 54 | I21: =H21 -> 54 | J21: =I21 -> 54 | K21: =J21 -> 54
B22: Paid-in capital & other equity | C22: ='Raw Data'!C80 -> 37704 | D22: ='Raw Data'!D80 -> 43134 | E22: ='Raw Data'!E80 -> 47908 | F22: =Schedules!F17 -> 49111.6 | G22: =F22 -> 49111.6 | H22: =Schedules!H17 -> 54218.465 | I22: =Schedules!I17 -> 59934.582 | J22: =Schedules!J17 -> 66020.194 | K22: =Schedules!K17 -> 71929.83
B23: Retained earnings | C23: ='Raw Data'!C52 -> 35209 | D23: ='Raw Data'!D52 -> 39003 | E23: ='Raw Data'!E52 -> 41381 | F23: =Schedules!F21 -> 42407.567 | G23: =F23 -> 42407.567 | H23: =Schedules!H21 -> 48105.487 | I23: =Schedules!I21 -> 56426.247 | J23: =Schedules!J21 -> 68297.565 | K23: =Schedules!K21 -> 84513.192
B24: Total stockholders' equity | C24: ='Raw Data'!C53 -> 72913 | D24: ='Raw Data'!D53 -> 82137 | E24: ='Raw Data'!E53 -> 89289 | F24: =F22+F23 -> 91519.167 | G24: =F24 -> 91519.167 | H24: =H22+H23 -> 102323.95 | I24: =I22+I23 -> 116360.83 | J24: =J22+J23 -> 134317.76 | K24: =K22+K23 -> 156443.02
B25: Noncontrolling interests | C25: ='Raw Data'!C54 -> 704 | D25: ='Raw Data'!D54 -> 670 | E25: ='Raw Data'!E54 -> 546 | F25: =Schedules!F25 -> 546 | G25: =F25 -> 546 | H25: =Schedules!H25 -> 546 | I25: =Schedules!I25 -> 546 | J25: =Schedules!J25 -> 546 | K25: =Schedules!K25 -> 546
B26: Total equity incl. NCI | C26: =C24+C25 -> 73617 | D26: =D24+D25 -> 82807 | E26: =E24+E25 -> 89835 | F26: =F24+F25 -> 92065.167 | G26: =F26 -> 92065.167 | H26: =H24+H25 -> 102869.95 | I26: =I24+I25 -> 116906.83 | J26: =J24+J25 -> 134863.76 | K26: =K24+K25 -> 156989.02
B27: Total liabilities & equity | C27: ='Raw Data'!C55 -> 122070 | D27: ='Raw Data'!D55 -> 137806 | E27: ='Raw Data'!E55 -> 157517 | F27: =F20+F21+F26 -> 162292.47 | G27: =F27 -> 162292.47 | H27: =H20+H21+H26 -> 176674.87 | I27: =I20+I21+I26 -> 202004.25 | J27: =J20+J21+J26 -> 231534.2 | K27: =K20+K21+K26 -> 265016.06
B28: Balance check | C28: =IF(ABS(C14-C27)<0.1,"Check","Error") -> Check | D28: =IF(ABS(D14-D27)<0.1,"Check","Error") -> Check | E28: =IF(ABS(E14-E27)<0.1,"Check","Error") -> Check | F28: =IF(ABS(F14-F27)<0.1,"Check","Error") -> Check | G28: =IF(ABS(G14-G27)<0.1,"Check","Error") -> Check | H28: =IF(ABS(H14-H27)<0.1,"Check","Error") -> Check | I28: =IF(ABS(I14-I27)<0.1,"Check","Error") -> Check | J28: =IF(ABS(J14-J27)<0.1,"Check","Error") -> Check | K28: =IF(ABS(K14-K27)<0.1,"Check","Error") -> Check
B29: Cash tie check | F29: =IF(ABS(F6-CF!F31)<0.1,"Check","Error") -> Check | G29: =IF(ABS(G6-CF!G31)<0.1,"Check","Error") -> Check | H29: =IF(ABS(H6-CF!H31)<0.1,"Check","Error") -> Check | I29: =IF(ABS(I6-CF!I31)<0.1,"Check","Error") -> Check | J29: =IF(ABS(J6-CF!J31)<0.1,"Check","Error") -> Check | K29: =IF(ABS(K6-CF!K31)<0.1,"Check","Error") -> Check

Sheet CF
B2: 现金流量表 / Cash Flow Statement
B3: Tesla, Inc. (NASDAQ: TSLA) | USD mn; indirect method | Valuation date: 2026-10-26
B5: Fiscal period | C5: 2024A | D5: 2025A | E5: 9M2026A | F5: Q4 2026E | G5: 2026E | H5: 2027E | I5: 2028E | J5: 2029E | K5: 2030E
B6: Net income | C6: ='Raw Data'!C56 -> 7153 | D6: ='Raw Data'!D56 -> 3855 | E6: ='Raw Data'!E56 -> 2423 | F6: =IS!F24 -> 1042.1996 | G6: =E6+F6 -> 3465.1996 | H6: =IS!H24 -> 5784.6912 | I6: =IS!I24 -> 8447.4715 | J6: =IS!J24 -> 12052.1 | K6: =IS!K24 -> 16462.566
B7: D&A and impairment | C7: ='Raw Data'!C57 -> 5368 | D7: ='Raw Data'!D57 -> 6148 | E7: ='Raw Data'!E57 -> 5061 | F7: =Schedules!F8 -> 1890.912 | G7: =E7+F7 -> 6951.912 | H7: =Schedules!H8 -> 7704.0106 | I7: =Schedules!I8 -> 9419.5293 | J7: =Schedules!J8 -> 11169.186 | K7: =Schedules!K8 -> 12468.883
B8: Stock-based compensation | C8: ='Raw Data'!C58 -> 1999 | D8: ='Raw Data'!D58 -> 2825 | E8: ='Raw Data'!E58 -> 3346 | F8: =Schedules!F15 -> 1203.6 | G8: =E8+F8 -> 4549.6 | H8: =Schedules!H15 -> 5106.8645 | I8: =Schedules!I15 -> 5716.117 | J8: =Schedules!J15 -> 6085.612 | K8: =Schedules!K15 -> 5909.636
B9: Other non-cash & operating items | C9: =C17-C6-C7-C8-SUM(C10:C15) -> 322 | D9: =D17-D6-D7-D8-SUM(D10:D15) -> 1277 | E9: =E17-E6-E7-E8-SUM(E10:E15) -> -301 | F9: =0 -> 0 | G9: =E9+F9 -> -301 | H9: =0 -> 0 | I9: =0 -> 0 | J9: =0 -> 0 | K9: =0 -> 0
B10: Change in accounts receivable | C10: ='Raw Data'!C59 -> -1083 | D10: ='Raw Data'!D59 -> -261 | E10: ='Raw Data'!E59 -> -188 | F10: =-(BS!F8-BS!E8) -> -310.30137 | G10: =E10+F10 -> -498.30137 | H10: =-(BS!H8-BS!F8) -> -300.47726 | I10: =-(BS!I8-BS!H8) -> -935.03503 | J10: =-(BS!J8-BS!I8) -> -963.71904 | K10: =-(BS!K8-BS!J8) -> -949.8591
B11: Change in inventory | C11: ='Raw Data'!C60 -> 937 | D11: ='Raw Data'!D60 -> -630 | E11: ='Raw Data'!E60 -> -1976 | F11: =-(BS!F9-BS!E9) -> -563.97808 | G11: =E11+F11 -> -2539.9781 | H11: =-(BS!H9-BS!F9) -> -799.98771 | I11: =-(BS!I9-BS!H9) -> -2624.4233 | J11: =-(BS!J9-BS!I9) -> -2649.173 | K11: =-(BS!K9-BS!J9) -> -2568.7842
B12: Change in operating lease vehicles | C12: ='Raw Data'!C61 -> -590 | D12: ='Raw Data'!D61 -> -25 | E12: ='Raw Data'!E61 -> 300 | F12: =0 -> 0 | G12: =E12+F12 -> 300 | H12: =0 -> 0 | I12: =0 -> 0 | J12: =0 -> 0 | K12: =0 -> 0
B13: Change in prepaid & other assets | C13: ='Raw Data'!C62 -> -3273 | D13: ='Raw Data'!D62 -> -3181 | E13: ='Raw Data'!E62 -> -2846 | F13: =-(BS!F10-BS!E10) -> -392.8 | G13: =E13+F13 -> -3238.8 | H13: =-(BS!H10-BS!F10) -> -402.13873 | I13: =-(BS!I10-BS!H10) -> -1251.3886 | J13: =-(BS!J10-BS!I10) -> -1289.7773 | K13: =-(BS!K10-BS!J10) -> -1271.2281
B14: Change in AP, accrued & other liabilities | C14: ='Raw Data'!C63 -> 3588 | D14: ='Raw Data'!D63 -> 4376 | E14: ='Raw Data'!E63 -> 7332 | F14: =(BS!F15-BS!E15)+(BS!F16-BS!E16) -> 930.70137 | G14: =E14+F14 -> 8262.7014 | H14: =(BS!H15-BS!F15)+(BS!H16-BS!F16) -> 2042.182 | I14: =(BS!I15-BS!H15)+(BS!I16-BS!H16) -> 6514.469 | J14: =(BS!J15-BS!I15)+(BS!J16-BS!I16) -> 6648.4153 | K14: =(BS!K15-BS!J15)+(BS!K16-BS!J16) -> 6502.8216
B15: Change in deferred revenue | C15: ='Raw Data'!C64 -> 502 | D15: ='Raw Data'!D64 -> 363 | E15: ='Raw Data'!E64 -> 1746 | F15: =(BS!F17-BS!E17) -> 841.8 | G15: =E15+F15 -> 2587.8 | H15: =(BS!H17-BS!F17) -> 584.92906 | I15: =(BS!I17-BS!H17) -> 1820.2015 | J15: =(BS!J17-BS!I17) -> 1876.0397 | K15: =(BS!K17-BS!J17) -> 1849.0591
B16: Change in other LT liabilities | C16: 0 | D16: 0 | E16: 0 | F16: =(BS!F19-BS!E19) -> 772.8 | G16: =E16+F16 -> 772.8 | H16: =(BS!H19-BS!F19) -> 950.50972 | I16: =(BS!I19-BS!H19) -> 2957.8275 | J16: =(BS!J19-BS!I19) -> 3048.5646 | K16: =(BS!K19-BS!J19) -> 3004.721
B17: Operating cash flow | C17: ='Raw Data'!C65 -> 14923 | D17: ='Raw Data'!D65 -> 14747 | E17: ='Raw Data'!E65 -> 14897 | F17: =SUM(F6:F16) -> 5414.9335 | G17: =E17+F17 -> 20311.934 | H17: =SUM(H6:H16) -> 20670.583 | I17: =SUM(I6:I16) -> 30064.769 | J17: =SUM(J6:J16) -> 35977.248 | K17: =SUM(K6:K16) -> 41407.815
B18: Capital expenditures | C18: ='Raw Data'!C66 -> -11342 | D18: ='Raw Data'!D66 -> -8527 | E18: ='Raw Data'!E66 -> -13014 | F18: =-Schedules!F7 -> -7000 | G18: =E18+F18 -> -20014 | H18: =-Schedules!H7 -> -22000 | I18: =-Schedules!I7 -> -24000 | J18: =-Schedules!J7 -> -22000 | K18: =-Schedules!K7 -> -20000
B19: Net short-term investment purchases | C19: =C21-C18 -> -7445 | D19: =D21-D18 -> -6951 | E19: =E21-E18 -> -1914 | F19: =-(BS!F7-BS!E7) -> 0 | G19: =E19+F19 -> -1914 | H19: =-(BS!H7-BS!F7) -> 0 | I19: =-(BS!I7-BS!H7) -> 0 | J19: =-(BS!J7-BS!I7) -> 0 | K19: =-(BS!K7-BS!J7) -> 0
B20: Other investing | C20: 0 | D20: 0 | E20: 0 | F20: =0 -> 0 | G20: =E20+F20 -> 0 | H20: =0 -> 0 | I20: =0 -> 0 | J20: =0 -> 0 | K20: =0 -> 0
B21: Investing cash flow | C21: ='Raw Data'!C67 -> -18787 | D21: ='Raw Data'!D67 -> -15478 | E21: ='Raw Data'!E67 -> -14928 | F21: =SUM(F18:F20) -> -7000 | G21: =E21+F21 -> -21928 | H21: =SUM(H18:H20) -> -22000 | I21: =SUM(I18:I20) -> -24000 | J21: =SUM(J18:J20) -> -22000 | K21: =SUM(K18:K20) -> -20000
B22: Debt issued | C22: ='Raw Data'!C68 -> 5744 | D22: ='Raw Data'!D68 -> 5586 | E22: ='Raw Data'!E68 -> 5834 | F22: =Schedules!F11 -> 0 | G22: =E22+F22 -> 5834 | H22: =Schedules!H11 -> 0 | I22: =Schedules!I11 -> 0 | J22: =Schedules!J11 -> 0 | K22: =Schedules!K11 -> 0
B23: Debt repaid | C23: ='Raw Data'!C69 -> -2500 | D23: ='Raw Data'!D69 -> -5546 | E23: ='Raw Data'!E69 -> -4954 | F23: =-Schedules!F12 -> 0 | G23: =E23+F23 -> -4954 | H23: =-Schedules!H12 -> 0 | I23: =-Schedules!I12 -> 0 | J23: =-Schedules!J12 -> 0 | K23: =-Schedules!K12 -> 0
B24: Equity issuance | C24: ='Raw Data'!C70 -> 1241 | D24: ='Raw Data'!D70 -> 1186 | E24: ='Raw Data'!E70 -> 782 | F24: =Schedules!F16 -> 0 | G24: =E24+F24 -> 782 | H24: =Schedules!H16 -> 0 | I24: =Schedules!I16 -> 0 | J24: =Schedules!J16 -> 0 | K24: =Schedules!K16 -> 0
B25: NCI distributions | C25: ='Raw Data'!C71 -> -104 | D25: ='Raw Data'!D71 -> -78 | E25: ='Raw Data'!E71 -> -126 | F25: =-Schedules!F24 -> -15.632994 | G25: =E25+F25 -> -141.63299 | H25: =-Schedules!H24 -> -86.770368 | I25: =-Schedules!I24 -> -126.71207 | J25: =-Schedules!J24 -> -180.78149 | K25: =-Schedules!K24 -> -246.93848
B26: Financing cash flow | C26: ='Raw Data'!C72 -> 3853 | D26: ='Raw Data'!D72 -> 1139 | E26: ='Raw Data'!E72 -> 1536 | F26: =SUM(F22:F25) -> -15.632994 | G26: =E26+F26 -> 1520.367 | H26: =SUM(H22:H25) -> -86.770368 | I26: =SUM(I22:I25) -> -126.71207 | J26: =SUM(J22:J25) -> -180.78149 | K26: =SUM(K22:K25) -> -246.93848
B27: FX effect | C27: ='Raw Data'!C73 -> -141 | D27: ='Raw Data'!D73 -> 171 | E27: ='Raw Data'!E73 -> -115 | F27: =0 -> 0 | G27: =E27+F27 -> -115 | H27: =0 -> 0 | I27: =0 -> 0 | J27: =0 -> 0 | K27: =0 -> 0
B28: Restricted cash / presentation adjustment | C28: 0 | D28: 0 | E28: 0 | F28: =0 -> 0 | G28: =E28+F28 -> 0 | H28: =0 -> 0 | I28: =0 -> 0 | J28: =0 -> 0 | K28: =0 -> 0
B29: Net change in cash | C29: =C31-C30 -> 16139 | D29: =D31-D30 -> 374 | E29: =E31-E30 -> 1340 | F29: =F17+F21+F26+F27+F28 -> -1600.6995 | G29: =E29+F29 -> -260.69948 | H29: =H17+H21+H26+H27+H28 -> -1416.187 | I29: =I17+I21+I26+I27+I28 -> 5938.0569 | J29: =J17+J21+J26+J27+J28 -> 13796.466 | K29: =K17+K21+K26+K27+K28 -> 21160.877
B30: Beginning cash & equivalents | D30: =C31 -> 16139 | E30: =D31 -> 16513 | F30: =BS!E6 -> 17853 | G30: =D31 -> 16513 | H30: =BS!F6 -> 16252.301 | I30: =BS!H6 -> 14836.114 | J30: =BS!I6 -> 20774.17 | K30: =BS!J6 -> 34570.637
B31: Ending cash & equivalents | C31: =BS!C6 -> 16139 | D31: =BS!D6 -> 16513 | E31: =BS!E6 -> 17853 | F31: =F30+F29 -> 16252.301 | G31: =F31 -> 16252.301 | H31: =H30+H29 -> 14836.114 | I31: =I30+I29 -> 20774.17 | J31: =J30+J29 -> 34570.637 | K31: =K30+K29 -> 55731.513
B32: Net income link check | C32: =IF(ABS(C6-IS!C24)<0.1,"Check","Error") -> Check | D32: =IF(ABS(D6-IS!D24)<0.1,"Check","Error") -> Check | E32: =IF(ABS(E6-IS!E24)<0.1,"Check","Error") -> Check | F32: =IF(ABS(F6-IS!F24)<0.1,"Check","Error") -> Check | G32: =IF(ABS(G6-IS!G24)<0.1,"Check","Error") -> Check | H32: =IF(ABS(H6-IS!H24)<0.1,"Check","Error") -> Check | I32: =IF(ABS(I6-IS!I24)<0.1,"Check","Error") -> Check | J32: =IF(ABS(J6-IS!J24)<0.1,"Check","Error") -> Check | K32: =IF(ABS(K6-IS!K24)<0.1,"Check","Error") -> Check

Sheet Schedules
B2: 支持表 / Supporting schedules
B3: Tesla, Inc. (NASDAQ: TSLA) | USD mn; roll-forwards | Valuation date: 2026-10-26
B5: Fiscal period | C5: 2024A | D5: 2025A | E5: 9M2026A | F5: Q4 2026E | G5: 2026E | H5: 2027E | I5: 2028E | J5: 2029E | K5: 2030E
B6: Opening fixed & leased operating assets | F6: =E9 -> 59091 | G6: =E6+F6 -> 59091 | H6: =F9 -> 64200.088 | I6: =H9 -> 78496.077 | J6: =I9 -> 93076.548 | K6: =J9 -> 103907.36
B7: Capital expenditures | C7: 11342 | D7: 8527 | E7: 13014 | F7: =Drivers!F28 -> 7000 | G7: =E7+F7 -> 20014 | H7: =Drivers!H28 -> 22000 | I7: =Drivers!I28 -> 24000 | J7: =Drivers!J28 -> 22000 | K7: =Drivers!K28 -> 20000
B8: D&A and impairment | C8: 5368 | D8: 6148 | E8: 5061 | F8: =F6*Drivers!F27 -> 1890.912 | G8: =E8+F8 -> 6951.912 | H8: =H6*Drivers!H27 -> 7704.0106 | I8: =I6*Drivers!I27 -> 9419.5293 | J8: =J6*Drivers!J27 -> 11169.186 | K8: =K6*Drivers!K27 -> 12468.883
B9: Ending fixed & leased operating assets | C9: ='Raw Data'!C76 -> 46341 | D9: ='Raw Data'!D76 -> 50159 | E9: ='Raw Data'!E76 -> 59091 | F9: =F6+F7-F8 -> 64200.088 | G9: =F9 -> 64200.088 | H9: =H6+H7-H8 -> 78496.077 | I9: =I6+I7-I8 -> 93076.548 | J9: =J6+J7-J8 -> 103907.36 | K9: =K6+K7-K8 -> 111438.48
B10: Opening debt & finance leases | F10: =E13 -> 9523 | G10: =E10+F10 -> 9523 | H10: =F13 -> 9523 | I10: =H13 -> 9523 | J10: =I13 -> 9523 | K10: =J13 -> 9523
B11: Debt issued | C11: 5744 | D11: 5586 | E11: 5834 | F11: =0 -> 0 | G11: =E11+F11 -> 5834 | H11: =0 -> 0 | I11: =0 -> 0 | J11: =0 -> 0 | K11: =0 -> 0
B12: Debt repaid | C12: 2500 | D12: 5546 | E12: 4954 | F12: =0 -> 0 | G12: =E12+F12 -> 4954 | H12: =0 -> 0 | I12: =0 -> 0 | J12: =0 -> 0 | K12: =0 -> 0
B13: Ending debt & finance leases | C13: ='Raw Data'!C79 -> 8213 | D13: ='Raw Data'!D79 -> 8376 | E13: ='Raw Data'!E79 -> 9523 | F13: =F10+F11-F12 -> 9523 | G13: =F13 -> 9523 | H13: =H10+H11-H12 -> 9523 | I13: =I10+I11-I12 -> 9523 | J13: =J10+J11-J12 -> 9523 | K13: =K10+K11-K12 -> 9523
B14: Opening paid-in capital & other equity | F14: =E17 -> 47908 | G14: =E14+F14 -> 47908 | H14: =F17 -> 49111.6 | I14: =H17 -> 54218.465 | J14: =I17 -> 59934.582 | K14: =J17 -> 66020.194
B15: Stock-based compensation | C15: 1999 | D15: 2825 | E15: 3346 | F15: =Drivers!F19*Drivers!F29 -> 1203.6 | G15: =E15+F15 -> 4549.6 | H15: =Drivers!H19*Drivers!H29 -> 5106.8645 | I15: =Drivers!I19*Drivers!I29 -> 5716.117 | J15: =Drivers!J19*Drivers!J29 -> 6085.612 | K15: =Drivers!K19*Drivers!K29 -> 5909.636
B16: Equity issuance | C16: 1241 | D16: 1186 | E16: 782 | F16: =0 -> 0 | G16: =E16+F16 -> 782 | H16: =0 -> 0 | I16: =0 -> 0 | J16: =0 -> 0 | K16: =0 -> 0
B17: Ending paid-in capital & other equity | C17: ='Raw Data'!C80 -> 37704 | D17: ='Raw Data'!D80 -> 43134 | E17: ='Raw Data'!E80 -> 47908 | F17: =F14+F15+F16 -> 49111.6 | G17: =F17 -> 49111.6 | H17: =H14+H15+H16 -> 54218.465 | I17: =I14+I15+I16 -> 59934.582 | J17: =J14+J15+J16 -> 66020.194 | K17: =K14+K15+K16 -> 71929.83
B18: Opening retained earnings | F18: =E21 -> 41381 | G18: =E18+F18 -> 41381 | H18: =F21 -> 42407.567 | I18: =H21 -> 48105.487 | J18: =I21 -> 56426.247 | K18: =J21 -> 68297.565
B19: Net income to common | C19: 7091 | D19: 3794 | E19: 2378 | F19: =IS!F26 -> 1026.5666 | G19: =E19+F19 -> 3404.5666 | H19: =IS!H26 -> 5697.9208 | I19: =IS!I26 -> 8320.7594 | J19: =IS!J26 -> 11871.318 | K19: =IS!K26 -> 16215.627
B20: Dividends | F20: =0 -> 0 | G20: =E20+F20 -> 0 | H20: =0 -> 0 | I20: =0 -> 0 | J20: =0 -> 0 | K20: =0 -> 0
B21: Ending retained earnings | C21: ='Raw Data'!C52 -> 35209 | D21: ='Raw Data'!D52 -> 39003 | E21: ='Raw Data'!E52 -> 41381 | F21: =F18+F19-F20 -> 42407.567 | G21: =F21 -> 42407.567 | H21: =H18+H19-H20 -> 48105.487 | I21: =I18+I19-I20 -> 56426.247 | J21: =J18+J19-J20 -> 68297.565 | K21: =K18+K19-K20 -> 84513.192
B22: Opening NCI | F22: =E25 -> 546 | G22: =E22+F22 -> 546 | H22: =F25 -> 546 | I22: =H25 -> 546 | J22: =I25 -> 546 | K22: =J25 -> 546
B23: NCI income | C23: 62 | D23: 61 | E23: 45 | F23: =IS!F25 -> 15.632994 | G23: =E23+F23 -> 60.632994 | H23: =IS!H25 -> 86.770368 | I23: =IS!I25 -> 126.71207 | J23: =IS!J25 -> 180.78149 | K23: =IS!K25 -> 246.93848
B24: NCI distributions | C24: 104 | D24: 78 | E24: 126 | F24: =F23 -> 15.632994 | G24: =E24+F24 -> 141.63299 | H24: =H23 -> 86.770368 | I24: =I23 -> 126.71207 | J24: =J23 -> 180.78149 | K24: =K23 -> 246.93848
B25: Ending NCI | C25: ='Raw Data'!C54 -> 704 | D25: ='Raw Data'!D54 -> 670 | E25: ='Raw Data'!E54 -> 546 | F25: =F22+F23-F24 -> 546 | G25: =F25 -> 546 | H25: =H22+H23-H24 -> 546 | I25: =I22+I23-I24 -> 546 | J25: =J22+J23-J24 -> 546 | K25: =K22+K23-K24 -> 546

Sheet DCF
B2: DCF 估值 / Unlevered free cash flow
B3: Tesla, Inc. (NASDAQ: TSLA) | USD mn except per-share; year-end discounting | Valuation date: 2026-10-26
B4: Active scenario | C4: =Assumptions!C4 -> Base
B6: UFCF build | C6: Q4 2026E | D6: 2027E | E6: 2028E | F6: 2029E | G6: 2030E
B7: Revenue | C7: =IS!F9 -> 30090 | D7: =IS!H9 -> 127671.61 | E7: =IS!I9 -> 150424.13 | F7: =IS!J9 -> 173874.63 | G7: =IS!K9 -> 196987.87
B8: EBIT | C8: =IS!F18 -> 960 | D8: =IS!H18 -> 5949.4619 | E8: =IS!I18 -> 9376.7174 | F8: =IS!J18 -> 13702.015 | G8: =IS!K18 -> 18733.025
B9: Normalized tax rate | C9: =Drivers!F30 -> 0.21 | D9: =Drivers!H30 -> 0.21 | E9: =Drivers!I30 -> 0.21 | F9: =Drivers!J30 -> 0.21 | G9: =Drivers!K30 -> 0.21
